Workbook

Sheet 00_PORTADA
A1: REGISTRO MAESTRO PROGRAMAS Y FICHAS DE COMUNICACIÓN Y SUSTENTABILIDAD SOCIAL
A2: Libro reorganizado para gestión, análisis y control de calidad de los programas sociales de PARACEL. Conserva las hojas originales y agrega capas ejecutivas, normalizadas y de verificación.
A4: Objetivo del libro | B4: Centralizar la trazabilidad documental, la estructura programática, los targets, los indicadores y las alertas de calidad del registro maestro.
A6: 01 | B6: 01_RESUMEN | C6: Vista ejecutiva con KPI, presupuesto consolidado y seguimiento por programa | E6: Indicadores de control
A7: 02 | B7: 02_MATRIZ_EJECUTIVA | C7: Matriz limpia de targets con campos derivados, presupuesto normalizado y semáforo de calidad | E7: Programas vigentes | F7: =COUNTIF('Programas Vigentes'!$J$2:$J$1000,"Vigente") -> 14
A8: 03 | B8: 03_INDICADORES_NORMALIZADOS | C8: Indicadores separados en filas para explotación analítica | E8: Programas con ficha | F8: =COUNTIF('Programas Vigentes'!$I$2:$I$1000,"Sí") -> 12
A9: 04 | B9: 04_CRONOGRAMA_TARGETS | C9: Calendario mensual de activación por target | E9: Programs sin ficha | F9: =COUNTIF('Programas Vigentes'!$I$2:$I$1000,"No") -> 2
A10: 06 | B10: 06_DICCIONARIO | C10: Definición de hojas, campos y criterios de mantenimiento | E10: Indicadores normalizados | F10: =COUNTA('03_INDICADORES_NORMALIZADOS'!$A$2:$A$5000) -> 228
A11: RAW | B11: Programas Vigentes | C11: Hoja original, catálogo de programas vigentes | E11: Alertas críticas | F11: =COUNTIF('02_MATRIZ_EJECUTIVA'!$AG$2:$AG$1000,"Crítico") -> 31
A12: RAW | B12: Historial Versiones | C12: Hoja original, historial documental
A13: RAW | B13: Fichas Técnicas | C13: Hoja original, consolidado de fichas
A14: RAW | B14: Targets por Ficha | C14: Hoja original, targets por ficha
A15: RAW | B15: Indicadores | C15: Hoja original, indicadores agregados
A16: RAW | B16: MATRIZ CONSOLIDADA | C16: Hoja original, matriz histórica consolidada

Sheet 01_RESUMEN
A1: 01. RESUMEN EJECUTIVO
A2: Síntesis del portafolio social, cobertura documental y calidad del registro maestro.
A4: Total programas | D4: Programas vigentes | G4: Programas con ficha | J4: Programas sin ficha
A5: =COUNTA('Programas Vigentes'!$A$2:$A$1000) -> 14 | D5: =COUNTIF('Programas Vigentes'!$J$2:$J$1000,"Vigente") -> 14 | G5: =COUNTIF('Programas Vigentes'!$I$2:$I$1000,"Sí") -> 12 | J5: =COUNTIF('Programas Vigentes'!$I$2:$I$1000,"No") -> 2
A7: Targets | D7: Indicadores individualizados | G7: Documentos en historial | J7: Presupuesto total normalizado
A8: =COUNTA('Targets por Ficha'!$A$2:$A$1000) -> 31 | D8: =COUNTA('03_INDICADORES_NORMALIZADOS'!$A$2:$A$5000) -> 228 | G8: =COUNTA('Historial Versiones'!$A$2:$A$2000) -> 100 | J8: =SUM('02_MATRIZ_EJECUTIVA'!$AC$5:$AC$1000) -> 414615
A11: Seguimiento por programa | K11: Hallazgos clave
A12: Código | B12: Programa | C12: Estado | D12: Tiene Ficha | E12: Targets | F12: Versiones | G12: Presupuesto (USD) | H12: Completitud Prom. | I12: Críticos | K12: La matriz ejecutiva contiene 31 registros de target.
A13: PR-SS-AAE | B13: Programa de Manejo Interno por Afectación de Tierras y Riesgos por Agentes Externos | C13: Vigente | D13: Sí | E13: =COUNTIF('02_MATRIZ_EJECUTIVA'!$B$5:$B$1000,A13) -> 2 | F13: 4 | G13: =SUMIF('02_MATRIZ_EJECUTIVA'!$B$5:$B$1000,A13,'02_MATRIZ_EJECUTIVA'!$AC$5:$AC$1000) -> 0 | H13: =IFERROR(AVERAGEIF('02_MATRIZ_EJECUTIVA'!$B$5:$B$1000,A13,'02_MATRIZ_EJECUTIVA'!$AE$5:$AE$1000),"") -> 0.588 | I13: =COUNTIFS('02_MATRIZ_EJECUTIVA'!$B$5:$B$1000,A13,'02_MATRIZ_EJECUTIVA'!$AG$5:$AG$1000,"Crítico") -> 2 | K13: Existen 2 programas vigentes sin ficha técnica explícita en el catálogo.
A14: PR-SS-CON | B14: Programa de Sensibilización y Seguimiento a Contratistas y Trabajadores | C14: Vigente | D14: Sí | E14: =COUNTIF('02_MATRIZ_EJECUTIVA'!$B$5:$B$1000,A14) -> 2 | F14: 4 | G14: =SUMIF('02_MATRIZ_EJECUTIVA'!$B$5:$B$1000,A14,'02_MATRIZ_EJECUTIVA'!$AC$5:$AC$1000) -> 0 | H14: =IFERROR(AVERAGEIF('02_MATRIZ_EJECUTIVA'!$B$5:$B$1000,A14,'02_MATRIZ_EJECUTIVA'!$AE$5:$AE$1000),"") -> 0.6175 | I14: =COUNTIFS('02_MATRIZ_EJECUTIVA'!$B$5:$B$1000,A14,'02_MATRIZ_EJECUTIVA'!$AG$5:$AG$1000,"Crítico") -> 2 | K14: Los campos de fórmula, fuente, periodicidad, responsable y evidencia se encuentran ampliamente incompletos en los targets.
A15: PR-SS-EMU | B15: Programa de Empoderamiento de la Mujer | C15: Vigente | D15: Sí | E15: =COUNTIF('02_MATRIZ_EJECUTIVA'!$B$5:$B$1000,A15) -> 2 | F15: 4 | G15: =SUMIF('02_MATRIZ_EJECUTIVA'!$B$5:$B$1000,A15,'02_MATRIZ_EJECUTIVA'!$AC$5:$AC$1000) -> 0 | H15: =IFERROR(AVERAGEIF('02_MATRIZ_EJECUTIVA'!$B$5:$B$1000,A15,'02_MATRIZ_EJECUTIVA'!$AE$5:$AE$1000),"") -> 0.647 | I15: =COUNTIFS('02_MATRIZ_EJECUTIVA'!$B$5:$B$1000,A15,'02_MATRIZ_EJECUTIVA'!$AG$5:$AG$1000,"Crítico") -> 2 | K15: La normalización de indicadores permite trabajar el seguimiento a nivel de indicador individual.
A16: PR-SS-MDO | B16: Programa de Desarrollo y Vinculación de Mano de Obra Local | C16: Vigente | D16: Sí | E16: =COUNTIF('02_MATRIZ_EJECUTIVA'!$B$5:$B$1000,A16) -> 2 | F16: 4 | G16: =SUMIF('02_MATRIZ_EJECUTIVA'!$B$5:$B$1000,A16,'02_MATRIZ_EJECUTIVA'!$AC$5:$AC$1000) -> 14851 | H16: =IFERROR(AVERAGEIF('02_MATRIZ_EJECUTIVA'!$B$5:$B$1000,A16,'02_MATRIZ_EJECUTIVA'!$AE$5:$AE$1000),"") -> 0.6175 | I16: =COUNTIFS('02_MATRIZ_EJECUTIVA'!$B$5:$B$1000,A16,'02_MATRIZ_EJECUTIVA'!$AG$5:$AG$1000,"Crítico") -> 2
A17: PR-SS-MSC | B17: Programa de Manejo Social | C17: Vigente | D17: Sí | E17: =COUNTIF('02_MATRIZ_EJECUTIVA'!$B$5:$B$1000,A17) -> 2 | F17: 4 | G17: =SUMIF('02_MATRIZ_EJECUTIVA'!$B$5:$B$1000,A17,'02_MATRIZ_EJECUTIVA'!$AC$5:$AC$1000) -> 14486 | H17: =IFERROR(AVERAGEIF('02_MATRIZ_EJECUTIVA'!$B$5:$B$1000,A17,'02_MATRIZ_EJECUTIVA'!$AE$5:$AE$1000),"") -> 0.647 | I17: =COUNTIFS('02_MATRIZ_EJECUTIVA'!$B$5:$B$1000,A17,'02_MATRIZ_EJECUTIVA'!$AG$5:$AG$1000,"Crítico") -> 2
A18: PR-SS-MSO | B18: Programa de Monitoreo Social | C18: Vigente | D18: No | E18: =COUNTIF('02_MATRIZ_EJECUTIVA'!$B$5:$B$1000,A18) -> 0 | F18: 4 | G18: =SUMIF('02_MATRIZ_EJECUTIVA'!$B$5:$B$1000,A18,'02_MATRIZ_EJECUTIVA'!$AC$5:$AC$1000) -> 0 | H18: =IFERROR(AVERAGEIF('02_MATRIZ_EJECUTIVA'!$B$5:$B$1000,A18,'02_MATRIZ_EJECUTIVA'!$AE$5:$AE$1000),"") | I18: =COUNTIFS('02_MATRIZ_EJECUTIVA'!$B$5:$B$1000,A18,'02_MATRIZ_EJECUTIVA'!$AG$5:$AG$1000,"Crítico") -> 0
A19: PR-SS-PCS | B19: Programa de Prevención y Gestión de Contingencias Sociales | C19: Vigente | D19: Sí | E19: =COUNTIF('02_MATRIZ_EJECUTIVA'!$B$5:$B$1000,A19) -> 2 | F19: 4 | G19: =SUMIF('02_MATRIZ_EJECUTIVA'!$B$5:$B$1000,A19,'02_MATRIZ_EJECUTIVA'!$AC$5:$AC$1000) -> 6708 | H19: =IFERROR(AVERAGEIF('02_MATRIZ_EJECUTIVA'!$B$5:$B$1000,A19,'02_MATRIZ_EJECUTIVA'!$AE$5:$AE$1000),"") -> 0.647 | I19: =COUNTIFS('02_MATRIZ_EJECUTIVA'!$B$5:$B$1000,A19,'02_MATRIZ_EJECUTIVA'!$AG$5:$AG$1000,"Crítico") -> 2
A20: PR-SS-PCU | B20: Programa de Gestión del Patrimonio Cultural | C20: Vigente | D20: Sí | E20: =COUNTIF('02_MATRIZ_EJECUTIVA'!$B$5:$B$1000,A20) -> 2 | F20: 4 | G20: =SUMIF('02_MATRIZ_EJECUTIVA'!$B$5:$B$1000,A20,'02_MATRIZ_EJECUTIVA'!$AC$5:$AC$1000) -> 0 | H20: =IFERROR(AVERAGEIF('02_MATRIZ_EJECUTIVA'!$B$5:$B$1000,A20,'02_MATRIZ_EJECUTIVA'!$AE$5:$AE$1000),"") -> 0.647 | I20: =COUNTIFS('02_MATRIZ_EJECUTIVA'!$B$5:$B$1000,A20,'02_MATRIZ_EJECUTIVA'!$AG$5:$AG$1000,"Crítico") -> 2
A21: PR-SS-PDP | B21: Programa de Promoción y Desarrollo de Empresas Proveedoras Locales | C21: Vigente | D21: Sí | E21: =COUNTIF('02_MATRIZ_EJECUTIVA'!$B$5:$B$1000,A21) -> 3 | F21: 4 | G21: =SUMIF('02_MATRIZ_EJECUTIVA'!$B$5:$B$1000,A21,'02_MATRIZ_EJECUTIVA'!$AC$5:$AC$1000) -> 0 | H21: =IFERROR(AVERAGEIF('02_MATRIZ_EJECUTIVA'!$B$5:$B$1000,A21,'02_MATRIZ_EJECUTIVA'!$AE$5:$AE$1000),"") -> 0.588 | I21: =COUNTIFS('02_MATRIZ_EJECUTIVA'!$B$5:$B$1000,A21,'02_MATRIZ_EJECUTIVA'!$AG$5:$AG$1000,"Crítico") -> 3
A22: PR-SS-QRI | B22: Programa de Gestión de Quejas, Consultas y Sugerencias | C22: Vigente | D22: Sí | E22: =COUNTIF('02_MATRIZ_EJECUTIVA'!$B$5:$B$1000,A22) -> 2 | F22: 4 | G22: =SUMIF('02_MATRIZ_EJECUTIVA'!$B$5:$B$1000,A22,'02_MATRIZ_EJECUTIVA'!$AC$5:$AC$1000) -> 0 | H22: =IFERROR(AVERAGEIF('02_MATRIZ_EJECUTIVA'!$B$5:$B$1000,A22,'02_MATRIZ_EJECUTIVA'!$AE$5:$AE$1000),"") -> 0.588 | I22: =COUNTIFS('02_MATRIZ_EJECUTIVA'!$B$5:$B$1000,A22,'02_MATRIZ_EJECUTIVA'!$AG$5:$AG$1000,"Crítico") -> 2
A23: PR-SS-RCI | B23: Programa de Relacionamiento con Comunidades e Inversión Social | C23: Vigente | D23: Sí | E23: =COUNTIF('02_MATRIZ_EJECUTIVA'!$B$5:$B$1000,A23) -> 2 | F23: 4 | G23: =SUMIF('02_MATRIZ_EJECUTIVA'!$B$5:$B$1000,A23,'02_MATRIZ_EJECUTIVA'!$AC$5:$AC$1000) -> 275831 | H23: =IFERROR(AVERAGEIF('02_MATRIZ_EJECUTIVA'!$B$5:$B$1000,A23,'02_MATRIZ_EJECUTIVA'!$AE$5:$AE$1000),"") -> 0.588 | I23: =COUNTIFS('02_MATRIZ_EJECUTIVA'!$B$5:$B$1000,A23,'02_MATRIZ_EJECUTIVA'!$AG$5:$AG$1000,"Crítico") -> 2
A24: PR-SS-RPI | B24: Programa de Relacionamiento con Comunidades Indígenas | C24: Vigente | D24: Sí | E24: =COUNTIF('02_MATRIZ_EJECUTIVA'!$B$5:$B$1000,A24) -> 6 | F24: 4 | G24: =SUMIF('02_MATRIZ_EJECUTIVA'!$B$5:$B$1000,A24,'02_MATRIZ_EJECUTIVA'!$AC$5:$AC$1000) -> 34350 | H24: =IFERROR(AVERAGEIF('02_MATRIZ_EJECUTIVA'!$B$5:$B$1000,A24,'02_MATRIZ_EJECUTIVA'!$AE$5:$AE$1000),"") -> 0.529 | I24: =COUNTIFS('02_MATRIZ_EJECUTIVA'!$B$5:$B$1000,A24,'02_MATRIZ_EJECUTIVA'!$AG$5:$AG$1000,"Crítico") -> 6
A25: PR-SS-SEV | B25: Programa de Seguridad Vial | C25: Vigente | D25: No | E25: =COUNTIF('02_MATRIZ_EJECUTIVA'!$B$5:$B$1000,A25) -> 0 | F25: 5 | G25: =SUMIF('02_MATRIZ_EJECUTIVA'!$B$5:$B$1000,A25,'02_MATRIZ_EJECUTIVA'!$AC$5:$AC$1000) -> 0 | H25: =IFERROR(AVERAGEIF('02_MATRIZ_EJECUTIVA'!$B$5:$B$1000,A25,'02_MATRIZ_EJECUTIVA'!$AE$5:$AE$1000),"") | I25: =COUNTIFS('02_MATRIZ_EJECUTIVA'!$B$5:$B$1000,A25,'02_MATRIZ_EJECUTIVA'!$AG$5:$AG$1000,"Crítico") -> 0
A26: PR-SS-SSC | B26: Programa de Salud y Seguridad Comunitaria | C26: Vigente | D26: Sí | E26: =COUNTIF('02_MATRIZ_EJECUTIVA'!$B$5:$B$1000,A26) -> 4 | F26: 5 | G26: =SUMIF('02_MATRIZ_EJECUTIVA'!$B$5:$B$1000,A26,'02_MATRIZ_EJECUTIVA'!$AC$5:$AC$1000) -> 68389 | H26: =IFERROR(AVERAGEIF('02_MATRIZ_EJECUTIVA'!$B$5:$B$1000,A26,'02_MATRIZ_EJECUTIVA'!$AE$5:$AE$1000),"") -> 0.647 | I26: =COUNTIFS('02_MATRIZ_EJECUTIVA'!$B$5:$B$1000,A26,'02_MATRIZ_EJECUTIVA'!$AG$5:$AG$1000,"Crítico") -> 4

Sheet 02_MATRIZ_EJECUTIVA
A1: 02. MATRIZ EJECUTIVA DE TARGETS
A2: Versión depurada de la matriz consolidada, se excluye el anexo histórico embebido y se agregan campos derivados para análisis y control.
A4: N° | B4: CÓDIGO PROGRAMA | C4: NOMBRE PROGRAMA | D4: VERSIÓN PROG. | E4: ESTADO | F4: NOMBRE FICHA | G4: VERSIÓN FICHA | H4: FECHA FICHA | I4: TARGET N° | J4: DESCRIPCIÓN TARGET | K4: ACTIVIDADES | L4: INDICADOR | M4: FÓRMULA DE CÁLCULO | N4: FUENTE DE VERIFICACIÓN | O4: PERIODICIDAD | P4: RESPONSABLE | Q4: EVIDENCIA | R4: PRODUCTOS | S4: RESULTADO ESPERADO | T4: PRESUPUESTO (USD) | U4: MESES ACTIVOS | V4: PROPÓSITO FICHA | W4: NECESIDAD | X4: OBJETIVO PROGRAMA | Y4: ALCANCE PROGRAMA | Z4: MARCO LEGAL | AA4: ID REGISTRO | AB4: AÑO FICHA | AC4: PRESUPUESTO NORMALIZADO (USD) | AD4: N° MESES ACTIVOS | AE4: % COMPLETITUD OPERATIVA | AF4: INCIDENCIAS | AG4: ESTADO CALIDAD
A5: 1 | B5: PR-SS-MDO | C5: Desarrollo y Vinculación de Mano de Obra Local | D5: v05 | E5: Vigente | F5: PROGRAMA DE DESARROLLO Y VINCULACIÓN CON LA MANO DE OBRA LOCAL | G5: v01 | H5: 45812 | I5: 1 | J5: Contribuir para aumentar el número de jóvenes y adultos con competencias técnicas y profesionales, para acceder al empleo (el trabajo decente) a través del desarrollo de [10] cursos de capacitación, y [8] jornadas de certificación laboral por competencias, en los componentes Forestal Industrial e I | K5: 1. Selección de organizaciones aliadas para el desarrollo de las capacitaciones y las certificaciones. 2. Suscribir convenios con instituciones educativas locales y nacionales con el fin de acordar un marco de cooperación para la formación y capacitación laboral del capital humano local y nacional. | L5: - Indicadores de Educación - Indicadores de Empleo | R5: 1 - Convenios / acuerdos. 2 - Curso de capacitación 3 - Jornadas de certificación. 4 - Base de datos de personas que culminaron los cursos y certificaciones. 4- Informe de línea de base. 5- Proyecto | S5: - Aumento del número de jóvenes y adultos con competencias técnicas y profesionales para acceder al empleo (trabajo decente). - Profesionales certificados para acceder al empleo (trabajo decente o | U5: May, Jun, Jul, Ago, Sep, Oct, Nov, Dic | V5: Desarrollar e instalar competencias y capacidades técnicas y profesionales en el área de influencia de Paracel | W5: - Falta de competencias técnicas y profesionales en la mano de obra local y departamental. - Centralización en la ciudad Concepción de los servicios de educación técnico y profesional. - Población | X5: Promover la generación de empleo local a través de la vinculación de mano de obra calificada y no calificada, [además del desarrollo e instalación de capacidades, en el área de influencia de Paracel]. | Y5: DEFINICIONES Área de Influencia Directa (AID) del componente industrial: incluyen 5 distritos cercanos al sitio de la Planta Industrial, incluyendo a 18 comunidades que se encuentran en un radio de 13 | AA5: =B5&"-T"&TEXT(I5,"00") -> PR-SS-MDO-T01 | AB5: =IF(H5="","",VALUE(LEFT(TEXT(H5,"yyyy-mm-dd"),4))) -> 2025 | AC5: 0 | AD5: =IF(U5="","",LEN(U5)-LEN(SUBSTITUTE(U5,",",""))+1) -> 8 | AE5: =ROUND((COUNTIF(J5,"<>") + COUNTIF(K5,"<>") + COUNTIF(L5,"<>") + COUNTIF(M5,"<>") + COUNTIF(N5,"<>") + COUNTIF(O5,"<>") + COUNTIF(P5,"<>") + COUNTIF(Q5,"<>") + COUNTIF(R5,"<>") + COUNTIF(S5,"<>") + COUNTIF(T5,"<>") + COUNTIF(U5,"<>") + COUNTIF(V5,"<>") + COUNTIF(W5,"<>") + COUNTIF(X5,"<>") + COUNTIF(Y5,"<>") + COUNTIF(Z5,"<>"))/17,3) -> 0.588 | AF5: =COUNTBLANK(M5:Q5)+IF(OR(T5="",T5="----"),1,0)+IF(U5="",1,0) -> 6 | AG5: =IF(AF5=0,"Completo",IF(AF5<=2,"Parcial","Crítico")) -> Crítico
A6: 2 | B6: PR-SS-MDO | C6: Desarrollo y Vinculación de Mano de Obra Local | D6: v05 | E6: Vigente | F6: PROGRAMA DE DESARROLLO Y VINCULACIÓN CON LA MANO DE OBRA LOCAL | G6: v01 | H6: 45812 | I6: 2 | J6: Becar a jóvenes de las comunidades del área e influencia de Paracel: - 10 jóvenes para educación en Bachiller Técnico. - 11 jóvenes para educación Terciaria. | K6: 1 - Seleccionar a las personas jóvenes conforme a criterios de elegibilidad. 2 - Medición de la línea de base. 3 - Buscar aliados estratégicos para la implementación del proyecto de becas (si aplica). 4 - Firma de carta compromiso. 5- Llamado interno para contar con voluntarios/as para el acompaña | L6: 1. Indicadores socioeconómicos. 2. Número de personas beneficiadas clasificadas por edad, sexo, comunidad, etnía. 3. Nivel academico alcanzado por los padres/tutores - hermanos/as mayores. 4. Número de instituciones alidas y especialidades. 5. Inversión mensual (seguimiento del presupuesto). 6. Horas al mes destinada por parte de padrinos/madrinas en el acompañamiento de las personas. 7. Reporte de calificaciones por período académico y por estudiante. | R6: Jóvenes con estudios técnicos y terciarios finalizados. | S6: Jóvenes con estudios técnicos y terciarios finalizados. | T6: 14.851 | U6: Feb, Mar, Abr, May, Jun, Jul, Ago, Sep, Oct, Nov, Dic | V6: Desarrollar e instalar competencias y capacidades técnicas y profesionales en el área de influencia de Paracel | W6: - Falta de competencias técnicas y profesionales en la mano de obra local y departamental. - Centralización en la ciudad Concepción de los servicios de educación técnico y profesional. - Población | X6: Promover la generación de empleo local a través de la vinculación de mano de obra calificada y no calificada, [además del desarrollo e instalación de capacidades, en el área de influencia de Paracel]. | Y6: DEFINICIONES Área de Influencia Directa (AID) del componente industrial: incluyen 5 distritos cercanos al sitio de la Planta Industrial, incluyendo a 18 comunidades que se encuentran en un radio de 13 | AA6: =B6&"-T"&TEXT(I6,"00") -> PR-SS-MDO-T02 | AB6: =IF(H6="","",VALUE(LEFT(TEXT(H6,"yyyy-mm-dd"),4))) -> 2025 | AC6: 14851 | AD6: =IF(U6="","",LEN(U6)-LEN(SUBSTITUTE(U6,",",""))+1) -> 11 | AE6: =ROUND((COUNTIF(J6,"<>") + COUNTIF(K6,"<>") + COUNTIF(L6,"<>") + COUNTIF(M6,"<>") + COUNTIF(N6,"<>") + COUNTIF(O6,"<>") + COUNTIF(P6,"<>") + COUNTIF(Q6,"<>") + COUNTIF(R6,"<>") + COUNTIF(S6,"<>") + COUNTIF(T6,"<>") + COUNTIF(U6,"<>") + COUNTIF(V6,"<>") + COUNTIF(W6,"<>") + COUNTIF(X6,"<>") + COUNTIF(Y6,"<>") + COUNTIF(Z6,"<>"))/17,3) -> 0.647 | AF6: =COUNTBLANK(M6:Q6)+IF(OR(T6="",T6="----"),1,0)+IF(U6="",1,0) -> 5 | AG6: =IF(AF6=0,"Completo",IF(AF6<=2,"Parcial","Crítico")) -> Crítico
A7: 3 | B7: PR-SS-EMU | C7: Empoderamiento de la Mujer | D7: v04 | E7: Vigente | F7: EMPODERAMIENTO DE LA MUJER | G7: v01 | H7: 45812 | I7: 1 | J7: Difundir la Ruta de Auxilio desarrollada en el año 2024 con foco en los siguientes municipios: Concepción, Paso Barreto, Sargento José Felix López, Paso Horqueta, alcanzando como mínimo al 80% de las comunidades del área de influencia de Paracel. | K7: 1. Selección de las áreas geográficas a ser intervenidas (componentes) y comunidades alcanzadas. 2. Difusión de los materiales. 3. Desarrollo del informe final. | L7: - Número de personas alcanzadas clasificadas sexo, edad, etnia, comunidad, institución, etc. - N° de materiales desarrollados y difundidos. | R7: 1. Materiales difundidos. 2. Informe final. | S7: Personas de las comunidades del área de influencia de Paracel con información la ruta de auxilio ante casos de violencia hacia las mujeres. | T7: 0 | U7: Jun, Jul, Oct, Nov, Dic | V7: Empoderar a las mujeres para acortar las brechas de desigualdad étnicas y de género. | W7: Las mujeres no participan plenamente de todos los sectores y todos los niveles de la actividad económica, y por ende no se construyen economías fuertes, y esto conlleva a no cumplir los objetivos de | X7: Empoderar a las mujeres para acortar las brechas de desigualdad étnicas y de género. | [FSC-STD-PRY-01-2022] Normas de Desempeño IFC REGISTROS Y/O ANEXO [Registro del Plan de Comunicación [Registro de | Y7: El programa de Empoderamiento de la Mujer tiene el siguiente alcance: DEFINICIONES Área de Influencia Directa (AID) del componente indígena: está compuesta por las comunidades indígenas ubicadas entr | AA7: =B7&"-T"&TEXT(I7,"00") -> PR-SS-EMU-T01 | AB7: =IF(H7="","",VALUE(LEFT(TEXT(H7,"yyyy-mm-dd"),4))) -> 2025 | AC7: 0 | AD7: =IF(U7="","",LEN(U7)-LEN(SUBSTITUTE(U7,",",""))+1) -> 5 | AE7: =ROUND((COUNTIF(J7,"<>") + COUNTIF(K7,"<>") + COUNTIF(L7,"<>") + COUNTIF(M7,"<>") + COUNTIF(N7,"<>") + COUNTIF(O7,"<>") + COUNTIF(P7,"<>") + COUNTIF(Q7,"<>") + COUNTIF(R7,"<>") + COUNTIF(S7,"<>") + COUNTIF(T7,"<>") + COUNTIF(U7,"<>") + COUNTIF(V7,"<>") + COUNTIF(W7,"<>") + COUNTIF(X7,"<>") + COUNTIF(Y7,"<>") + COUNTIF(Z7,"<>"))/17,3) -> 0.647 | AF7: =COUNTBLANK(M7:Q7)+IF(OR(T7="",T7="----"),1,0)+IF(U7="",1,0) -> 5 | AG7: =IF(AF7=0,"Completo",IF(AF7<=2,"Parcial","Crítico")) -> Crítico
A8: 4 | B8: PR-SS-EMU | C8: Empoderamiento de la Mujer | D8: v04 | E8: Vigente | F8: EMPODERAMIENTO DE LA MUJER | G8: v01 | H8: 45812 | I8: 2 | J8: Fortalecer la red de apoyo para las mujeres de la Región de Concepción desarrollando como mínimo 3 espacios. | K8: 1. Propiciar espacios de intercambio de conocimientos, experiencias y aprendizajes con la red de mujeres y referentes invitadas por Paracel. 2. Desarrollo del informe final. | L8: - Número de personas que participaron de los espacios desagregadas por sexo, edad, etnia, organización, etc. - Número de horas de los espacios. - Número de espacios propociados. - Número de temas abordados. - Número de personas invitadas. - Número de personas vinculadas al proyecto externas a Paracel (por actividad). - Inversión. - Conocimiento de las personas antes y despues de la participación de los espacios. | R8: 1. Informe final. | S8: Mujeres de la red de apoyo con mayor conocimiento para afrontar los desafíos de las mujeres en la sociedad. | T8: 0 | U8: Jul, Sep, Nov, Dic | V8: Empoderar a las mujeres para acortar las brechas de desigualdad étnicas y de género. | W8: Las mujeres no participan plenamente de todos los sectores y todos los niveles de la actividad económica, y por ende no se construyen economías fuertes, y esto conlleva a no cumplir los objetivos de | X8: Empoderar a las mujeres para acortar las brechas de desigualdad étnicas y de género. | [FSC-STD-PRY-01-2022] Normas de Desempeño IFC REGISTROS Y/O ANEXO [Registro del Plan de Comunicación [Registro de | Y8: El programa de Empoderamiento de la Mujer tiene el siguiente alcance: DEFINICIONES Área de Influencia Directa (AID) del componente indígena: está compuesta por las comunidades indígenas ubicadas entr | AA8: =B8&"-T"&TEXT(I8,"00") -> PR-SS-EMU-T02 | AB8: =IF(H8="","",VALUE(LEFT(TEXT(H8,"yyyy-mm-dd"),4))) -> 2025 | AC8: 0 | AD8: =IF(U8="","",LEN(U8)-LEN(SUBSTITUTE(U8,",",""))+1) -> 4 | AE8: =ROUND((COUNTIF(J8,"<>") + COUNTIF(K8,"<>") + COUNTIF(L8,"<>") + COUNTIF(M8,"<>") + COUNTIF(N8,"<>") + COUNTIF(O8,"<>") + COUNTIF(P8,"<>") + COUNTIF(Q8,"<>") + COUNTIF(R8,"<>") + COUNTIF(S8,"<>") + COUNTIF(T8,"<>") + COUNTIF(U8,"<>") + COUNTIF(V8,"<>") + COUNTIF(W8,"<>") + COUNTIF(X8,"<>") + COUNTIF(Y8,"<>") + COUNTIF(Z8,"<>"))/17,3) -> 0.647 | AF8: =COUNTBLANK(M8:Q8)+IF(OR(T8="",T8="----"),1,0)+IF(U8="",1,0) -> 5 | AG8: =IF(AF8=0,"Completo",IF(AF8<=2,"Parcial","Crítico")) -> Crítico
A9: 5 | B9: PR-SS-CON | C9: Sensibilización y Seguimiento a Contratistas y Trabajadores | D9: v05 | E9: Vigente | F9: GESTIÓN DE EMPRESAS CONTRATISTAS | G9: v00 | H9: 45812 | I9: 1 | J9: Auditar de forma trimestral a empresas contratistas del componente Forestal e Industrial (si aplica) en materia de sustentabilidad social considerando las normativas nacionales e internacionales adoptadas por Paracel, en el marco del respeto de los derechos de los pueblos indígenas y comunidades rur | K9: 1. Selección de empresas contratistas a ser auditadas (el número de empresas puede aumentar dependiendo de los hallazgos de No Conformidades). 2. Desarrollo de las auditorías trimestrales. 3. Acompañamiento mensual para la revisión de los planes de acciones correctivas para el cierre de los hallazgo | L9: - Número de empresas auditadas. - Proporción de empresas auditadas con relación al número total de empresas. - Número total de hallazgos. - Número total de observaciones y oportunidades de mejora. - Porcentaje de cierre de los hallazgos y de manera general. - Porcentaje de cumplimiento de plazos de cierre de los hallazgos y de manera general. - Cantidad de acompañamientos. | R9: Informes de Auditoría Manual de Buenas Prácticas de Manufactura. | S9: - Cumplimiento de las normativas nacionales e internaciones. - Respeto en la vinculación con comunidades indígenas y rurales. | T9: ---- | U9: Ene, Feb, Mar, Abr, May, Jun, Jul, Ago, Sep, Oct, Nov, Dic | V9: Acompañar y monitorear a [empresas contratistas y trabajadores/as] para asegurar el cumplimiento de las normativas nacionales y [estándares de sostenibilidad internacionales en materia social]. Monito | W9: Incumplimiento de normativas nacionales e estándares internacionales, y de los requisitos establecidos por Paracel a las empresas proveedoras por falta de conocimineto y experiencia por parte de empre | X9: Acompañar y monitorear a [empresas contratistas y trabajadores/as] para asegurar el cumplimiento de las normativas nacionales y [estándares de sostenibilidad internacionales en materia social]. Monito | Y9: [Este programa tiene el siguiente alcance]: DEFINICIONES Área de Influencia Directa (AID) del componente forestal: incluye a [6] distritos en los que se localizan las áreas de las plantaciones foresta | AA9: =B9&"-T"&TEXT(I9,"00") -> PR-SS-CON-T01 | AB9: =IF(H9="","",VALUE(LEFT(TEXT(H9,"yyyy-mm-dd"),4))) -> 2025 | AC9: 0 | AD9: =IF(U9="","",LEN(U9)-LEN(SUBSTITUTE(U9,",",""))+1) -> 12 | AE9: =ROUND((COUNTIF(J9,"<>") + COUNTIF(K9,"<>") + COUNTIF(L9,"<>") + COUNTIF(M9,"<>") + COUNTIF(N9,"<>") + COUNTIF(O9,"<>") + COUNTIF(P9,"<>") + COUNTIF(Q9,"<>") + COUNTIF(R9,"<>") + COUNTIF(S9,"<>") + COUNTIF(T9,"<>") + COUNTIF(U9,"<>") + COUNTIF(V9,"<>") + COUNTIF(W9,"<>") + COUNTIF(X9,"<>") + COUNTIF(Y9,"<>") + COUNTIF(Z9,"<>"))/17,3) -> 0.647 | AF9: =COUNTBLANK(M9:Q9)+IF(OR(T9="",T9="----"),1,0)+IF(U9="",1,0) -> 6 | AG9: =IF(AF9=0,"Completo",IF(AF9<=2,"Parcial","Crítico")) -> Crítico
A10: 6 | B10: PR-SS-CON | C10: Sensibilización y Seguimiento a Contratistas y Trabajadores | D10: v05 | E10: Vigente | F10: GESTIÓN DE EMPRESAS CONTRATISTAS | G10: v00 | H10: 45812 | I10: 2 | J10: Sensibilizar al 100% de las empresas contratistas del componente forestal e industrial [(si aplica)] en temas relacionados [a las normas nacionales, estándares internacionales y procesos documentales adoptados de Paracel]. | K10: 1. Desarrollar un plan de capacitación para las áreas administrativas de las empresas contratistas, sobre principios establecidos en los estándares y procesos documentales adoptados por Paracel. 2. Implementar las capacitaciones conforme al plan de capacitación. 3. Identificar en campo, situacion | L10: - Número de personas participantes clasificados por organización, cargo, rango etario, sexo, comunidad, etnia. - Número de horas de capacitación. - Número de temas desarrollados. - Datos sobre conocimiento del tema antes de iniciar los talleres y conocimientos adquiridos posterior a los talleres. - Porcentaje de participación con relación al número total de empresas y trabajadores/as. - Porcentaje de uso del presupuesto de manera mensual. | R10: Plan de Capacitación Capacitaciones | S10: Empresas más sensibilizadas y con conocimiento. | U10: Mar, Jun, Jul, Ago, Sep, Nov, Dic | V10: Acompañar y monitorear a [empresas contratistas y trabajadores/as] para asegurar el cumplimiento de las normativas nacionales y [estándares de sostenibilidad internacionales en materia social]. Monito | W10: Incumplimiento de normativas nacionales e estándares internacionales, y de los requisitos establecidos por Paracel a las empresas proveedoras por falta de conocimineto y experiencia por parte de empre | X10: Acompañar y monitorear a [empresas contratistas y trabajadores/as] para asegurar el cumplimiento de las normativas nacionales y [estándares de sostenibilidad internacionales en materia social]. Monito | Y10: [Este programa tiene el siguiente alcance]: DEFINICIONES Área de Influencia Directa (AID) del componente forestal: incluye a [6] distritos en los que se localizan las áreas de las plantaciones foresta | AA10: =B10&"-T"&TEXT(I10,"00") -> PR-SS-CON-T02 | AB10: =IF(H10="","",VALUE(LEFT(TEXT(H10,"yyyy-mm-dd"),4))) -> 2025 | AC10: 0 | AD10: =IF(U10="","",LEN(U10)-LEN(SUBSTITUTE(U10,",",""))+1) -> 7 | AE10: =ROUND((COUNTIF(J10,"<>") + COUNTIF(K10,"<>") + COUNTIF(L10,"<>") + COUNTIF(M10,"<>") + COUNTIF(N10,"<>") + COUNTIF(O10,"<>") + COUNTIF(P10,"<>") + COUNTIF(Q10,"<>") + COUNTIF(R10,"<>") + COUNTIF(S10,"<>") + COUNTIF(T10,"<>") + COUNTIF(U10,"<>") + COUNTIF(V10,"<>") + COUNTIF(W10,"<>") + COUNTIF(X10,"<>") + COUNTIF(Y10,"<>") + COUNTIF(Z10,"<>"))/17,3) -> 0.588 | AF10: =COUNTBLANK(M10:Q10)+IF(OR(T10="",T10="----"),1,0)+IF(U10="",1,0) -> 6 | AG10: =IF(AF10=0,"Completo",IF(AF10<=2,"Parcial","Crítico")) -> Crítico
A11: 7 | B11: PR-SS-SSC | C11: Salud y Seguridad Comunitaria | D11: v06 | E11: Vigente | F11: SALUD Y SEGURIDAD COMUNITARIA | G11: v01 | H11: 45812 | I11: 1 | J11: Posibilitar la asistencia médica a aproximadamente 1.500 personas de comunidades del área de influencia de Paracel reduciendo la brecha de acceso a los programas y servicios nacionales de salud en el período 2025. | K11: 1.Lograr una vinculación cercana con las Unidades de Salud Familiar y los Centros de Salud del ADA y AID y con el Ministerio de Salud Pública y Bienestar Social, [a través de las regionales de salud de Concepción y Amambay]. 2.Selección de las comunidades a ser beneficiadas con las asistencias médic | L11: - Número de alianzas firmadas. - Número de personas que participaron de las asistencia desagregadas por sexo, edad, etnia, comunidad, etc. - Número de USF intervenidas. - Número de especialidades médicas por asistencia. - Número de personas vinculadas al programa externas a Paracel (por actividad). - Monto de inversión directa o indirecta por parte de las organizaciones aliadas (por actividad). - Porcentaje de uso del presupuesto mensual. | R11: 1. Convenios 2. Informe de línea de base. 3. Registros de servicios. 4. Informe final. | S11: 1.500 personas asistidas | T11: . 16.585 | U11: Ene, Feb, Mar, Abr, May, Jun, Jul, Ago, Sep, Oct, Nov, Dic | V11: Implementar un programa eficiente para promover el cuidado de la higiene, la seguridad y la salud de la población con énfasis en la prevención de enfermedades que pudieran relacionarse con el aumento | W11: Poco acceso a servicios de salud por parte de los miembros de las comunidades y falta de conocimiento sobre planificación familiar y ETS. | X11: Implementar un programa eficiente para promover el cuidado de la higiene, la seguridad y la salud de la población con énfasis en la prevención de enfermedades que pudieran relacionarse con el aumento | Y11: El programa de Salud y Seguridad Comunitaria tiene el siguiente alcance: DEFINICIONES Área de Influencia Directa (AID) del componente industrial: incluyen 5 distritos cercanos al sitio de la Planta In | AA11: =B11&"-T"&TEXT(I11,"00") -> PR-SS-SSC-T01 | AB11: =IF(H11="","",VALUE(LEFT(TEXT(H11,"yyyy-mm-dd"),4))) -> 2025 | AC11: 16585 | AD11: =IF(U11="","",LEN(U11)-LEN(SUBSTITUTE(U11,",",""))+1) -> 12 | AE11: =ROUND((COUNTIF(J11,"<>") + COUNTIF(K11,"<>") + COUNTIF(L11,"<>") + COUNTIF(M11,"<>") + COUNTIF(N11,"<>") + COUNTIF(O11,"<>") + COUNTIF(P11,"<>") + COUNTIF(Q11,"<>") + COUNTIF(R11,"<>") + COUNTIF(S11,"<>") + COUNTIF(T11,"<>") + COUNTIF(U11,"<>") + COUNTIF(V11,"<>") + COUNTIF(W11,"<>") + COUNTIF(X11,"<>") + COUNTIF(Y11,"<>") + COUNTIF(Z11,"<>"))/17,3) -> 0.647 | AF11: =COUNTBLANK(M11:Q11)+IF(OR(T11="",T11="----"),1,0)+IF(U11="",1,0) -> 5 | AG11: =IF(AF11=0,"Completo",IF(AF11<=2,"Parcial","Crítico")) -> Crítico
A12: 8 | B12: PR-SS-SSC | C12: Salud y Seguridad Comunitaria | D12: v06 | E12: Vigente | F12: SALUD Y SEGURIDAD COMUNITARIA | G12: v01 | H12: 45812 | I12: 2 | J12: Distribuir 10.000 kilos de leche del Programa Alimentario Nutricional Integral (PANI) con un alcance de 5.000 personas en el período 2025. | K12: 1. Generar alianzas con la Primera Región Sanitaria. 2. Seleccionar las USF a ser intervenidas (PANI). 3. Distribución y entrega de las leches en las USF seleccionadas. 4. Selección de las USF a ser intervenidas (PAI). 5. Jornadas de inmunización en comunidades de la zona de influencia de Paracel. | L12: - Número de alianzas firmadas. - Número de personas alcanzadas en la distribución de leche desagregadas por sexo, edad, etnia, comunidad, etc. - Número de personas alcanzadas en jornadas de inmunización. - Número de USF intervenidas. - Número de personas vinculadas al programa externas a Paracel (por actividad). - Monto de inversión directa o indirecta por parte de las organizaciones aliadas (por actividad). - Porcentaje de uso del presupuesto mensual. | R12: 1. Convenios 2. Informe de línea de base. 3. Registros de servicios. 4. Informe final. | S12: 5.000 personas beneficiadas. | T12: 11.155 = 6.494 + 4.661 | U12: Ene, Feb, Mar, Abr, May, Jun, Jul, Ago, Sep, Oct, Nov, Dic | V12: Implementar un programa eficiente para promover el cuidado de la higiene, la seguridad y la salud de la población con énfasis en la prevención de enfermedades que pudieran relacionarse con el aumento | W12: Poco acceso a servicios de salud por parte de los miembros de las comunidades y falta de conocimiento sobre planificación familiar y ETS. | X12: Implementar un programa eficiente para promover el cuidado de la higiene, la seguridad y la salud de la población con énfasis en la prevención de enfermedades que pudieran relacionarse con el aumento | Y12: El programa de Salud y Seguridad Comunitaria tiene el siguiente alcance: DEFINICIONES Área de Influencia Directa (AID) del componente industrial: incluyen 5 distritos cercanos al sitio de la Planta In | AA12: =B12&"-T"&TEXT(I12,"00") -> PR-SS-SSC-T02 | AB12: =IF(H12="","",VALUE(LEFT(TEXT(H12,"yyyy-mm-dd"),4))) -> 2025 | AC12: 11155 | AD12: =IF(U12="","",LEN(U12)-LEN(SUBSTITUTE(U12,",",""))+1) -> 12 | AE12: =ROUND((COUNTIF(J12,"<>") + COUNTIF(K12,"<>") + COUNTIF(L12,"<>") + COUNTIF(M12,"<>") + COUNTIF(N12,"<>") + COUNTIF(O12,"<>") + COUNTIF(P12,"<>") + COUNTIF(Q12,"<>") + COUNTIF(R12,"<>") + COUNTIF(S12,"<>") + COUNTIF(T12,"<>") + COUNTIF(U12,"<>") + COUNTIF(V12,"<>") + COUNTIF(W12,"<>") + COUNTIF(X12,"<>") + COUNTIF(Y12,"<>") + COUNTIF(Z12,"<>"))/17,3) -> 0.647 | AF12: =COUNTBLANK(M12:Q12)+IF(OR(T12="",T12="----"),1,0)+IF(U12="",1,0) -> 5 | AG12: =IF(AF12=0,"Completo",IF(AF12<=2,"Parcial","Crítico")) -> Crítico
A13: 9 | B13: PR-SS-SSC | C13: Salud y Seguridad Comunitaria | D13: v06 | E13: Vigente | F13: SALUD Y SEGURIDAD COMUNITARIA | G13: v01 | H13: 45812 | I13: 3 | J13: Sensibilizar a miembros de las comunidades de la zona de influencia de Paracel sobre educación sexual, planificación familiar y prevención de VIH/SIDA, a través de talleres, entrega de insumos, la aplicación de las pruebas de detección de VIH y la vinculación con el sistema de salud local. | K13: 1. Generar alianzas con la Cruz Roja Paraguaya, la Primera Región Sanitaria y el PRONASIDA. 2. Desarrollar capacitaciones / talleres sobre salud sexual y reproductiva, incluidos los de planificación familiar. Ayudar a tomar conciencia acerca de enfermedades y su prevención, por ejemplo, según las ci | L13: - Número de alianzas generadas. - Número comunidades abordadas. - Número de personas beneficiadas desagregadas por sexo, edad, etnia, comunidad, etc. - Número de personas vinculadas al programa externas a Paracel (por actividad). - Monto de inversión directa o indirecta por parte de las organizaciones aliadas (por actividad). - Porcentaje de uso del presupuesto mensual. - Número de testeos realizados. - Número de colaboradores/as de empresas contratistas abordados/as. | R13: 1. Convenio 2. Sistematización de los talleres (materiales, contenido, etc.). 3. Informe final. | S13: Comunidades sensibilizadas en temas relacionados a Prevención de VIH|SIDA, Planificación Familiar y testeos. | T13: . 10.649 | U13: Mar, Abr, May, Jun, Jul, Ago, Sep, Oct, Nov, Dic | V13: Implementar un programa eficiente para promover el cuidado de la higiene, la seguridad y la salud de la población con énfasis en la prevención de enfermedades que pudieran relacionarse con el aumento | W13: Poco acceso a servicios de salud por parte de los miembros de las comunidades y falta de conocimiento sobre planificación familiar y ETS. | X13: Implementar un programa eficiente para promover el cuidado de la higiene, la seguridad y la salud de la población con énfasis en la prevención de enfermedades que pudieran relacionarse con el aumento | Y13: El programa de Salud y Seguridad Comunitaria tiene el siguiente alcance: DEFINICIONES Área de Influencia Directa (AID) del componente industrial: incluyen 5 distritos cercanos al sitio de la Planta In | AA13: =B13&"-T"&TEXT(I13,"00") -> PR-SS-SSC-T03 | AB13: =IF(H13="","",VALUE(LEFT(TEXT(H13,"yyyy-mm-dd"),4))) -> 2025 | AC13: 10649 | AD13: =IF(U13="","",LEN(U13)-LEN(SUBSTITUTE(U13,",",""))+1) -> 10 | AE13: =ROUND((COUNTIF(J13,"<>") + COUNTIF(K13,"<>") + COUNTIF(L13,"<>") + COUNTIF(M13,"<>") + COUNTIF(N13,"<>") + COUNTIF(O13,"<>") + COUNTIF(P13,"<>") + COUNTIF(Q13,"<>") + COUNTIF(R13,"<>") + COUNTIF(S13,"<>") + COUNTIF(T13,"<>") + COUNTIF(U13,"<>") + COUNTIF(V13,"<>") + COUNTIF(W13,"<>") + COUNTIF(X13,"<>") + COUNTIF(Y13,"<>") + COUNTIF(Z13,"<>"))/17,3) -> 0.647 | AF13: =COUNTBLANK(M13:Q13)+IF(OR(T13="",T13="----"),1,0)+IF(U13="",1,0) -> 5 | AG13: =IF(AF13=0,"Completo",IF(AF13<=2,"Parcial","Crítico")) -> Crítico
A14: 10 | B14: PR-SS-SSC | C14: Salud y Seguridad Comunitaria | D14: v06 | E14: Vigente | F14: SALUD Y SEGURIDAD COMUNITARIA | G14: v01 | H14: 45812 | I14: 4 | J14: Apoyar al Ministerio de la Niñez y Adolescencia en la prevención de la violencia hacia la niñez y la adolescencia, en las comunidades del área de influencia de Paracel. | K14: 1. Planificar las acciones considerando el marco de cooperación | selección de las comunidades. 2. Implementación de las actividades planificadas. | L14: - Número de personas formadas como facilitadoras. - Número de instituciones representadas. - Número de personas alcanzadas en espacios de sensibilización clasificadas por edad y sexo. - Número de materiales entregados. | R14: Informe final. | S14: Personas formadas y sensibilizadas en prevencion de violencia hacia niñez y la adolescencia. | T14: . 30.000 | U14: Mar, Abr, May, Jun, Jul, Ago, Sep, Oct, Nov | V14: Implementar un programa eficiente para promover el cuidado de la higiene, la seguridad y la salud de la población con énfasis en la prevención de enfermedades que pudieran relacionarse con el aumento | W14: Poco acceso a servicios de salud por parte de los miembros de las comunidades y falta de conocimiento sobre planificación familiar y ETS. | X14: Implementar un programa eficiente para promover el cuidado de la higiene, la seguridad y la salud de la población con énfasis en la prevención de enfermedades que pudieran relacionarse con el aumento | Y14: El programa de Salud y Seguridad Comunitaria tiene el siguiente alcance: DEFINICIONES Área de Influencia Directa (AID) del componente industrial: incluyen 5 distritos cercanos al sitio de la Planta In | AA14: =B14&"-T"&TEXT(I14,"00") -> PR-SS-SSC-T04 | AB14: =IF(H14="","",VALUE(LEFT(TEXT(H14,"yyyy-mm-dd"),4))) -> 2025 | AC14: 30000 | AD14: =IF(U14="","",LEN(U14)-LEN(SUBSTITUTE(U14,",",""))+1) -> 9 | AE14: =ROUND((COUNTIF(J14,"<>") + COUNTIF(K14,"<>") + COUNTIF(L14,"<>") + COUNTIF(M14,"<>") + COUNTIF(N14,"<>") + COUNTIF(O14,"<>") + COUNTIF(P14,"<>") + COUNTIF(Q14,"<>") + COUNTIF(R14,"<>") + COUNTIF(S14,"<>") + COUNTIF(T14,"<>") + COUNTIF(U14,"<>") + COUNTIF(V14,"<>") + COUNTIF(W14,"<>") + COUNTIF(X14,"<>") + COUNTIF(Y14,"<>") + COUNTIF(Z14,"<>"))/17,3) -> 0.647 | AF14: =COUNTBLANK(M14:Q14)+IF(OR(T14="",T14="----"),1,0)+IF(U14="",1,0) -> 5 | AG14: =IF(AF14=0,"Completo",IF(AF14<=2,"Parcial","Crítico")) -> Crítico
A15: 11 | B15: PR-SS-MSC | C15: Manejo Social | D15: v05 | E15: Vigente | F15: MANEJO SOCIAL | G15: v01 | H15: 45813 | I15: 1 | J15: Realizar espacios informativos en el año, en las comunidades del área de influencia directa de Paracel. | K15: 1. Reuniones semestrales con pobladores del ADA, AID y con las comunidades indígena para transferir información sobre Paracel, acompañar y monitorear la percepción de los mismos con relación a Paracel. 2. Toma de datos acerca de la percepción de las personas y datos sobre migración. | L15: 1. Número de personas participantes por comunidad clasificadas, por edad, sexo, franja etaria, comunidad, etnia. 2. Índice de percepción. 3. Datos sobre migración 4. Materiales desarrollados. 5. Número de personas de las diferentes áreas de Paracel participantes. | R15: - Informe de percepción. - Materiales informativos | educativos desarrollados. | S15: - Miembros de las comunidades informados. - Mejora continua en nuestros procesos con relación a expectativas de los miembros de las comunidades. | T15: 8.442 | U15: Jul, Nov | V15: Identificar las afectaciones generadas por la empresa, buscando minimizarlas, con foco en las comunidades del área de influencia de Paracel. | W15: Contar con información sobre la percepción y expectativas de los miembros de las comunidades con relación a desempeño de Paracel, a fin de establacer acciones de mejora. | X15: Identificar las afectaciones generadas por la empresa, buscando minimizarlas, con foco en las comunidades del área de influencia de Paracel. | [FSC-STD-PRY-01-2022] Normas de Desempeño IFC REGISTROS Y | Y15: El programa de Manejo Social tiene el siguiente alcance: DEFINICIONES Área Directamente Afectada (ADA) del componente industrial: unidades sociales y comunidades situadas en el entorno inmediato de la | AA15: =B15&"-T"&TEXT(I15,"00") -> PR-SS-MSC-T01 | AB15: =IF(H15="","",VALUE(LEFT(TEXT(H15,"yyyy-mm-dd"),4))) -> 2025 | AC15: 8442 | AD15: =IF(U15="","",LEN(U15)-LEN(SUBSTITUTE(U15,",",""))+1) -> 2 | AE15: =ROUND((COUNTIF(J15,"<>") + COUNTIF(K15,"<>") + COUNTIF(L15,"<>") + COUNTIF(M15,"<>") + COUNTIF(N15,"<>") + COUNTIF(O15,"<>") + COUNTIF(P15,"<>") + COUNTIF(Q15,"<>") + COUNTIF(R15,"<>") + COUNTIF(S15,"<>") + COUNTIF(T15,"<>") + COUNTIF(U15,"<>") + COUNTIF(V15,"<>") + COUNTIF(W15,"<>") + COUNTIF(X15,"<>") + COUNTIF(Y15,"<>") + COUNTIF(Z15,"<>"))/17,3) -> 0.647 | AF15: =COUNTBLANK(M15:Q15)+IF(OR(T15="",T15="----"),1,0)+IF(U15="",1,0) -> 5 | AG15: =IF(AF15=0,"Completo",IF(AF15<=2,"Parcial","Crítico")) -> Crítico
A16: 12 | B16: PR-SS-MSC | C16: Manejo Social | D16: v05 | E16: Vigente | F16: MANEJO SOCIAL | G16: v01 | H16: 45813 | I16: 2 | J16: Alinear expectativas de miembros de las comunidades y otros grupos de interés acerca del funcionamiento de Paracel e inversiones sociales. | K16: 1. Reuniones semestrales con los líderes y lideresas de las comunidades rurales e indígenas del área de influencia de Paracel, para la socialización y actualización de las actividades desarrolladas en el marco de los programas sociales de la empresa. 2. Alinear expectativas de líderes y líderesas d | L16: 1. Número de personas participantes por comunidad clasificadas, por edad, sexo, franja etaria, comunidad, etnia. 2. Índice de percepción. 3. Materiales desarrollados. 4. Número de personas de las diferentes áreas de Paracel participantes. | R16: - Informe de percepción. - Materiales informativos | educativos desarrollados. | S16: - Líderes y lideresas de las comunidades informados/as. - Mejora continua en nuestros procesos con relación a expectativas de los miembros de las comunidades. | T16: 6.044 | U16: Jul, Nov | V16: Identificar las afectaciones generadas por la empresa, buscando minimizarlas, con foco en las comunidades del área de influencia de Paracel. | W16: Contar con información sobre la percepción y expectativas de los miembros de las comunidades con relación a desempeño de Paracel, a fin de establacer acciones de mejora. | X16: Identificar las afectaciones generadas por la empresa, buscando minimizarlas, con foco en las comunidades del área de influencia de Paracel. | [FSC-STD-PRY-01-2022] Normas de Desempeño IFC REGISTROS Y | Y16: El programa de Manejo Social tiene el siguiente alcance: DEFINICIONES Área Directamente Afectada (ADA) del componente industrial: unidades sociales y comunidades situadas en el entorno inmediato de la | AA16: =B16&"-T"&TEXT(I16,"00") -> PR-SS-MSC-T02 | AB16: =IF(H16="","",VALUE(LEFT(TEXT(H16,"yyyy-mm-dd"),4))) -> 2025 | AC16: 6044 | AD16: =IF(U16="","",LEN(U16)-LEN(SUBSTITUTE(U16,",",""))+1) -> 2 | AE16: =ROUND((COUNTIF(J16,"<>") + COUNTIF(K16,"<>") + COUNTIF(L16,"<>") + COUNTIF(M16,"<>") + COUNTIF(N16,"<>") + COUNTIF(O16,"<>") + COUNTIF(P16,"<>") + COUNTIF(Q16,"<>") + COUNTIF(R16,"<>") + COUNTIF(S16,"<>") + COUNTIF(T16,"<>") + COUNTIF(U16,"<>") + COUNTIF(V16,"<>") + COUNTIF(W16,"<>") + COUNTIF(X16,"<>") + COUNTIF(Y16,"<>") + COUNTIF(Z16,"<>"))/17,3) -> 0.647 | AF16: =COUNTBLANK(M16:Q16)+IF(OR(T16="",T16="----"),1,0)+IF(U16="",1,0) -> 5 | AG16: =IF(AF16=0,"Completo",IF(AF16<=2,"Parcial","Crítico")) -> Crítico
A17: 13 | B17: PR-SS-PCS | C17: Prevención y Gestión de Contingencias Sociales | D17: v05 | E17: Vigente | F17: PREVENCIÓN CONTINGENCIAS SOCIALES | G17: v01 | H17: 45817 | I17: 1 | J17: Fortalecer la prevención de incendios forestales en 8 comunidades del área de influencia de Paracel mediante acciones de concientización y capacitación. Además, lograr la conformación de una brigada comunitaria. | K17: 1- Contratar a la empresa consultora para el desarrollo de los talleres, y/o generar alianzas. 2- Identificación y selección de comunidades a intervenir con el desarrollo de los espacios de concientización y capacitación de prevención de incendios forestales. 3- Desarrollo de talleres rurales partic | L17: 1. N° de talleres realizados. 2. N° de personas participantes. 3. N° de personas que conforman la brigada. 4. N° de personas entrenadas. 5. N° de reuniones y acuerdos realizados. | R17: - Informe final de actividades. - Materiales informativos - educativos desarrollados. - Informe de datos acerca de conocimientos adquiridos. | S17: - Prevención de incendios forestales. - Mejora en los procesos de respuesta e intervención en casos de incendios forestales. | T17: 5.887 | U17: Jun, Jul, Ago, Sep, Oct | V17: Prevenir y dar una pronta respuesta ante contingencias sociales, tanto en las etapas constructiva y operativa de Paracel en su componente industrial, como en las etapas de instalación, operación y man | W17: Gestionar de forma adecuada las respuestas ante las contingencias sociales que pudieran ser generadas a raíz de las intervenciones operacionales de Paracel con los diferentes grupos de interés. | X17: Prevenir y dar una pronta respuesta ante contingencias sociales, tanto en las etapas constructiva y operativa de Paracel en su componente industrial, como en las etapas de instalación, operación y man | Y17: El programa de Prevención y Gestión de Contingencias Sociales tiene el siguiente alcance: DEFINICIONES Área de Influencia Directa (AID) del componente industrial: incluyen 5 distritos cercanos al siti | AA17: =B17&"-T"&TEXT(I17,"00") -> PR-SS-PCS-T01 | AB17: =IF(H17="","",VALUE(LEFT(TEXT(H17,"yyyy-mm-dd"),4))) -> 2025 | AC17: 5887 | AD17: =IF(U17="","",LEN(U17)-LEN(SUBSTITUTE(U17,",",""))+1) -> 5 | AE17: =ROUND((COUNTIF(J17,"<>") + COUNTIF(K17,"<>") + COUNTIF(L17,"<>") + COUNTIF(M17,"<>") + COUNTIF(N17,"<>") + COUNTIF(O17,"<>") + COUNTIF(P17,"<>") + COUNTIF(Q17,"<>") + COUNTIF(R17,"<>") + COUNTIF(S17,"<>") + COUNTIF(T17,"<>") + COUNTIF(U17,"<>") + COUNTIF(V17,"<>") + COUNTIF(W17,"<>") + COUNTIF(X17,"<>") + COUNTIF(Y17,"<>") + COUNTIF(Z17,"<>"))/17,3) -> 0.647 | AF17: =COUNTBLANK(M17:Q17)+IF(OR(T17="",T17="----"),1,0)+IF(U17="",1,0) -> 5 | AG17: =IF(AF17=0,"Completo",IF(AF17<=2,"Parcial","Crítico")) -> Crítico
A18: 14 | B18: PR-SS-PCS | C18: Prevención y Gestión de Contingencias Sociales | D18: v05 | E18: Vigente | F18: PREVENCIÓN CONTINGENCIAS SOCIALES | G18: v01 | H18: 45817 | I18: 1 | J18: Además, lograr la conformación de una brigada comunitaria. | K18: 1. Selección de organización con experiencia para la conformación de la brigada comunitaria en la comunidad indígena Takuarita. 2. Taller rural participativo para la conformación de brigada comunitaria con la comunidad indígena Takuarita. 3. Desarrollo del entrenamiento de la brigada comunitaria, a | L18: 1. N° de talleres realizados. 2. N° de personas participantes. 3. N° de personas que conforman la brigada. 4. N° de personas entrenadas. 5. N° de reuniones y acuerdos realizados. | R18: - Brigada comunitaria conformada. | S18: - Prevención de incendios forestales y capacidad de respuesta ante situaciones críticas. | T18: 821 | U18: Jun, Jul, Ago, Sep | V18: Prevenir y dar una pronta respuesta ante contingencias sociales, tanto en las etapas constructiva y operativa de Paracel en su componente industrial, como en las etapas de instalación, operación y man | W18: Gestionar de forma adecuada las respuestas ante las contingencias sociales que pudieran ser generadas a raíz de las intervenciones operacionales de Paracel con los diferentes grupos de interés. | X18: Prevenir y dar una pronta respuesta ante contingencias sociales, tanto en las etapas constructiva y operativa de Paracel en su componente industrial, como en las etapas de instalación, operación y man | Y18: El programa de Prevención y Gestión de Contingencias Sociales tiene el siguiente alcance: DEFINICIONES Área de Influencia Directa (AID) del componente industrial: incluyen 5 distritos cercanos al siti | AA18: =B18&"-T"&TEXT(I18,"00") -> PR-SS-PCS-T01 | AB18: =IF(H18="","",VALUE(LEFT(TEXT(H18,"yyyy-mm-dd"),4))) -> 2025 | AC18: 821 | AD18: =IF(U18="","",LEN(U18)-LEN(SUBSTITUTE(U18,",",""))+1) -> 4 | AE18: =ROUND((COUNTIF(J18,"<>") + COUNTIF(K18,"<>") + COUNTIF(L18,"<>") + COUNTIF(M18,"<>") + COUNTIF(N18,"<>") + COUNTIF(O18,"<>") + COUNTIF(P18,"<>") + COUNTIF(Q18,"<>") + COUNTIF(R18,"<>") + COUNTIF(S18,"<>") + COUNTIF(T18,"<>") + COUNTIF(U18,"<>") + COUNTIF(V18,"<>") + COUNTIF(W18,"<>") + COUNTIF(X18,"<>") + COUNTIF(Y18,"<>") + COUNTIF(Z18,"<>"))/17,3) -> 0.647 | AF18: =COUNTBLANK(M18:Q18)+IF(OR(T18="",T18="----"),1,0)+IF(U18="",1,0) -> 5 | AG18: =IF(AF18=0,"Completo",IF(AF18<=2,"Parcial","Crítico")) -> Crítico
A19: 15 | B19: PR-SS-AAE | C19: Manejo Interno por Afectación de Tierras y Riesgos por Agentes Externos | D19: v05 | E19: Vigente | F19: MANEJO INTERNO POR AFECTACIÓN DE TIERRAS Y RIESGO POR AGENTES EXTERNOS | G19: v00 | H19: 45819 | I19: 1 | J19: Contar con acuerdos de servidumbre de paso con el 100% de las estancias vecinas de las propiedades forestales con el fin de garantizar el libre tránsito de los miembros de Paracel y empresas contratistas. | K19: 1.Actualización del mapeo de las propiedades utilizadas como acceso y salida (componente forestal e indígena), [con el área de Seguridad Corporativa para el diseño del corredor de accesos y/o caminos alternativos a ser utilizados por personas externas a Paracel y empresas contratistas. 2. Elaboració | L19: 1- N° de propiedades a ser utilizadas como servidumbre de paso 2- N° de documentos elaborados 3- N° de comunicados elaborados 4- N° de comunicados emitidos 5- N° de reuniones 6- N° de personas participantes 7- N° de acuerdos firmados | R19: Acuerdos de servidumbre de paso. | S19: Granatizar el libre tránsito de los miembros de Paracel y empresas contratistas. | U19: Jun, Jul, Ago, Sep, Oct, Nov, Dic | V19: Prevenir conflictos con terceros (propietarios/as de inmuebles utilizados como servidumbre) y delinear protocolos internos para garantizar la seguridad de las personas que conforman los equipos de Par | W19: Formalizar los acuerdos con propietarios/as de inmuebles vecinos y con miembros de las comunidades en caso de que aplique con relación al uso de caminos. Reducir los riesgos de conflictos. | X19: Prevenir conflictos con terceros ([propietarios/as] de inmuebles utilizados como servidumbre) y delinear protocolos internos para garantizar la seguridad de las personas que conforman los equipos de P | Y19: [El alcance del programa se presenta a continuación]: DEFINICIONES Área de Influencia Directa (AID) del componente forestal: incluye a [6] distritos en los que se localizan las áreas de las plantacion | AA19: =B19&"-T"&TEXT(I19,"00") -> PR-SS-AAE-T01 | AB19: =IF(H19="","",VALUE(LEFT(TEXT(H19,"yyyy-mm-dd"),4))) -> 2025 | AC19: 0 | AD19: =IF(U19="","",LEN(U19)-LEN(SUBSTITUTE(U19,",",""))+1) -> 7 | AE19: =ROUND((COUNTIF(J19,"<>") + COUNTIF(K19,"<>") + COUNTIF(L19,"<>") + COUNTIF(M19,"<>") + COUNTIF(N19,"<>") + COUNTIF(O19,"<>") + COUNTIF(P19,"<>") + COUNTIF(Q19,"<>") + COUNTIF(R19,"<>") + COUNTIF(S19,"<>") + COUNTIF(T19,"<>") + COUNTIF(U19,"<>") + COUNTIF(V19,"<>") + COUNTIF(W19,"<>") + COUNTIF(X19,"<>") + COUNTIF(Y19,"<>") + COUNTIF(Z19,"<>"))/17,3) -> 0.588 | AF19: =COUNTBLANK(M19:Q19)+IF(OR(T19="",T19="----"),1,0)+IF(U19="",1,0) -> 6 | AG19: =IF(AF19=0,"Completo",IF(AF19<=2,"Parcial","Crítico")) -> Crítico
A20: 16 | B20: PR-SS-AAE | C20: Manejo Interno por Afectación de Tierras y Riesgos por Agentes Externos | D20: v05 | E20: Vigente | F20: MANEJO INTERNO POR AFECTACIÓN DE TIERRAS Y RIESGO POR AGENTES EXTERNOS | G20: v00 | H20: 45819 | I20: 2 | J20: Velar porque el 100% de colaboradores/as de empresas proveedoras de servicio de seguridad corporativa se encuentren sensibilizados/as en materia de Derechos Humanos. | K20: 1. Solicitar al área de Compras/Seguridad Corporativa un informe trimestral sobre registros de entrenamiento en temas de Derechos Humanos a colaboradores/as de empresas proveedoras de servicios de seguridad y control de acceso. Paracel resguardará que estas personas no ejerzan “abusos de poder”. 2. | L20: 1- N° de personas trabajando en el área de seguridad y control de acceso (clasificadas, edad, sexo, comunidad, etnia, región, etc.). 2- N° de personas formadas en materia de Derechos Humanos clasificados por edad, sexo, empresa, carga horaria, temas. 3- N° de verificaciones realizadas en campo clasificadas por empresas. 4- N° de hallazgos en las verificaciones de campo. 5- N° de cierre de hallazgos resultantes de las verificaciones en campo. | R20: Informes | S20: Reducir la probabilidad de que existan desvíos en la conducta del equipo de seguridad con relación a temas de Derechos Humanos. | U20: Jun, Sep, Dic | V20: Prevenir conflictos con terceros (propietarios/as de inmuebles utilizados como servidumbre) y delinear protocolos internos para garantizar la seguridad de las personas que conforman los equipos de Par | W20: Formalizar los acuerdos con propietarios/as de inmuebles vecinos y con miembros de las comunidades en caso de que aplique con relación al uso de caminos. Reducir los riesgos de conflictos. | X20: Prevenir conflictos con terceros ([propietarios/as] de inmuebles utilizados como servidumbre) y delinear protocolos internos para garantizar la seguridad de las personas que conforman los equipos de P | Y20: [El alcance del programa se presenta a continuación]: DEFINICIONES Área de Influencia Directa (AID) del componente forestal: incluye a [6] distritos en los que se localizan las áreas de las plantacion | AA20: =B20&"-T"&TEXT(I20,"00") -> PR-SS-AAE-T02 | AB20: =IF(H20="","",VALUE(LEFT(TEXT(H20,"yyyy-mm-dd"),4))) -> 2025 | AC20: 0 | AD20: =IF(U20="","",LEN(U20)-LEN(SUBSTITUTE(U20,",",""))+1) -> 3 | AE20: =ROUND((COUNTIF(J20,"<>") + COUNTIF(K20,"<>") + COUNTIF(L20,"<>") + COUNTIF(M20,"<>") + COUNTIF(N20,"<>") + COUNTIF(O20,"<>") + COUNTIF(P20,"<>") + COUNTIF(Q20,"<>") + COUNTIF(R20,"<>") + COUNTIF(S20,"<>") + COUNTIF(T20,"<>") + COUNTIF(U20,"<>") + COUNTIF(V20,"<>") + COUNTIF(W20,"<>") + COUNTIF(X20,"<>") + COUNTIF(Y20,"<>") + COUNTIF(Z20,"<>"))/17,3) -> 0.588 | AF20: =COUNTBLANK(M20:Q20)+IF(OR(T20="",T20="----"),1,0)+IF(U20="",1,0) -> 6 | AG20: =IF(AF20=0,"Completo",IF(AF20<=2,"Parcial","Crítico")) -> Crítico
A21: 17 | B21: PR-SS-QRI | C21: Gestión de Quejas, Consultas y Sugerencias | D21: v05 | E21: Vigente | F21: GESTIÓN DE QUEJAS, CONSULTAS Y SUGERENCIAS | G21: v01 | H21: 45826 | I21: 1 | J21: El 100% de casos ingresados a través de los diferentes canales establecidos por Paracel atendidos/gestionados. | K21: 1. Funcionamiento del canal externo de atención de quejas. 2. Socializar el procedimiento de gestión de quejas, sugerencias y consultas con todas las partes interesadas de Paracel y los canales correspondientes. 3. Seguimiento y verificación del funcionamiento del sistema de gestión de quejas, suger | L21: - Número de quejas, consultas y sugerencias clasificadas por tipo y origen interno (nómina) y externo (contratistas y comunidad). - Número de actividades/acciones de socialización. - Número de personas alcanzadas en medios digitales en procesos de socialización. - Número de capacitaciones realizadas, número de personas alcanzadas clasificadas por edad, sexo, comunidad, etnia, empresa. - Horas de capacitación. - Número de quejas relacionadas al Código de Ética clasificadas por origen. - Porcentaje de procesos cerrados. - Porcentaje de uso del presupuesto de manera mensual. - Porcentaje de satifacción con el canal (proceso). | R21: - Sistema de gestión de quejas, sugerencias y consultas. - Informe de seguimientiento a las quejas consultas y sugerencias de las comunidades indígenas. | S21: Canalización, atención y direccionamiento, de las quejas, consultas y sugerencias de la población y las comunidades indígenas. | U21: Ene, Feb, Mar, Abr, May, Jun, Jul, Ago, Sep, Oct, Nov, Dic | V21: Garantizar atención a las quejas, sugerencias y consultas de la población de las áreas de influencia de Paracel, colaboradores/as propios/as y de empresas proveedoras, pueblos indígenas y de la poblac | W21: Temores y expectativas generadas en la población y las comunidades indígenas, afectación de la red social y comunitaria, de los servicios ecosistémicos, cambio en la calidad de vida, usos y costumbres | X21: Garantizar atención a las quejas, sugerencias y consultas de la población de las áreas de influencia de Paracel, [colaboradores/as propios/as y de empresas proveedoras], pueblos indígenas y de la pobl | Y21: Este programa es transversal a: DEFINICIONES Área de Influencia Directa (AID) del componente industrial: incluyen 5 distritos cercanos al sitio de la Planta Industrial, incluyendo a 18 comunidades que | AA21: =B21&"-T"&TEXT(I21,"00") -> PR-SS-QRI-T01 | AB21: =IF(H21="","",VALUE(LEFT(TEXT(H21,"yyyy-mm-dd"),4))) -> 2025 | AC21: 0 | AD21: =IF(U21="","",LEN(U21)-LEN(SUBSTITUTE(U21,",",""))+1) -> 12 | AE21: =ROUND((COUNTIF(J21,"<>") + COUNTIF(K21,"<>") + COUNTIF(L21,"<>") + COUNTIF(M21,"<>") + COUNTIF(N21,"<>") + COUNTIF(O21,"<>") + COUNTIF(P21,"<>") + COUNTIF(Q21,"<>") + COUNTIF(R21,"<>") + COUNTIF(S21,"<>") + COUNTIF(T21,"<>") + COUNTIF(U21,"<>") + COUNTIF(V21,"<>") + COUNTIF(W21,"<>") + COUNTIF(X21,"<>") + COUNTIF(Y21,"<>") + COUNTIF(Z21,"<>"))/17,3) -> 0.588 | AF21: =COUNTBLANK(M21:Q21)+IF(OR(T21="",T21="----"),1,0)+IF(U21="",1,0) -> 6 | AG21: =IF(AF21=0,"Completo",IF(AF21<=2,"Parcial","Crítico")) -> Crítico
